<?xml version="1.0"?>
<robot name="bb_8" xmlns:xacro="http://ros.org/wiki/xacro">
  <xacro:include filename="$(find bb_8_description)/urdf/bb_8.gazebo.xacro"/>
  
  <link name="base_link">
    <inertial>
      <origin xyz="0 0 -0.3" rpy="0 0 0" />
      <mass value="5" />
      <inertia 
        ixx="0.02" ixy="0.0" ixz="0.0"
        iyy="0.02" iyz="0.0"
        izz="0.02" />
    </inertial>
    <visual>
      <origin xyz="0 0 0" rpy="0 0 0" />
      <geometry>
        <sphere radius="0.1" />
      </geometry>
    </visual>
  </link>
  
  <joint name="rotation_joint" type="continuous">
    <origin xyz="0 0 0" rpy="0 0 0" />
    <parent link="base_link" />
    <child link="base_rotation_link" />
    <axis xyz="0 0 1" />
  </joint>
  
  <link name="base_rotation_link">
    <inertial>
      <origin xyz="0 0 -0.35" rpy="0 0 0" />
      <mass value="0.1" />
      <inertia 
        ixx="0.0004" ixy="0.0" ixz="0.0" 
        iyy="0.0004" iyz="0.0" 
        izz="0.0004" />
    </inertial>
    <collision>
      <origin xyz="0 0 0" rpy="0 0 0" />
      <geometry>
        <sphere radius="0.1" />
      </geometry>
    </collision>
    <visual>
      <origin xyz="0 0 0" rpy="0 0 0" />
      <geometry>
        <sphere radius="0.1" />
      </geometry>  
    </visual>
  </link>
    
  <joint name="direction_joint" type="continuous">
    <origin rpy="0 0 0" xyz="0 0 0" />
    <parent link="base_rotation_link" />
    <child link="base_direction_link" />
    <axis xyz="0 1 0" />
  </joint>

  <link name="base_direction_link">
    <inertial>
      <origin xyz="0 0 0" rpy="0 0 0" />
      <mass value="0.1" />
      <inertia 
        ixx="0.0004" ixy="0.0" ixz="0.0" 
        iyy="0.0004" iyz="0.0" 
        izz="0.0004" />
    </inertial>
    <collision>
      <origin xyz="0 0 0" rpy="0 0 0" />
      <geometry>
        <sphere radius="0.35" />
      </geometry>
    </collision>
    <visual>
      <origin xyz="0 0 -0.35" rpy="0 0 0" />
      <geometry>
        <mesh filename="package://bb_8_description/meshes/bb8-body/bb8-body.dae" scale="1 1 1"/>
      </geometry>
    </visual>
  </link>

  <joint name="head_joint" type="continuous">
    <origin xyz="0 0 0" rpy="0 0 0" />
    <parent link="base_rotation_link" />
    <child link="head_link" />
    <axis xyz="0 0 1" />
  </joint>
  
  <link name="head_link">
    <inertial>
      <origin xyz="0 0 0" rpy="0 0 0" />
      <mass value="0.1" />
      <inertia 
        ixx="0.0004" ixy="0.0" ixz="0.0" 
        iyy="0.0004" iyz="0.0" 
        izz="0.0004" />
    </inertial>
    <collision>
      <origin xyz="0 0 0" rpy="0 0 0" />
      <geometry>
        <sphere radius="0.2" />
      </geometry>
    </collision>
    <visual>
      <origin xyz="0 0 -0.35" rpy="0 0 0" />
      <geometry>
        <mesh filename="package://bb_8_description/meshes/bb8-head/bb8-head.dae" scale="1 1 1"/>
      </geometry>
    </visual>
  </link>
    
  <joint name="scan_joint" type="fixed">
    <origin xyz="0 0 0" rpy="0 0 0"/>
    <parent link="base_rotation_link"/>
    <child link="base_scan"/>
  </joint>
  
  <link name="base_scan"/>
  
</robot>
